{"id":11728,"className":"javax.naming.NamingException","methodName":"initCause","signature":"\u003cjavax.naming.NamingException: java.lang.Throwable initCause(java.lang.Throwable)\u003e","javadoc":"/** \n * Initializes the cause of this exception to the specified value. The cause is the throwable that caused this naming exception to be thrown. \u003cp\u003e This method may be called at most once.\n * @param cause   the cause, which is saved for later retrieval bythe  {@link #getCause()} method.  A \u003ctt\u003enull\u003c/tt\u003e valueindicates that the cause is nonexistent or unknown.\n * @return a reference to this \u003ccode\u003eNamingException\u003c/code\u003e instance.\n * @throws IllegalArgumentException if \u003ccode\u003ecause\u003c/code\u003e is thisexception.  (A throwable cannot be its own cause.)\n * @throws IllegalStateException if this method has alreadybeen called on this exception.\n * @see #getCause\n * @since 1.4\n */\n","tf":{"freq":{"call":2,"save":1,"link":1,"state":1,"alreadybeen":1,"specifi":1,"refer":1,"byth":1,"name":2,"valu":1,"initi":1,"argument":1,"may":1,"thrown":1,"except":6,"nonexist":1,"later":1,"init":1,"valueind":1,"unknown":1,"illeg":2,"instanc":1,"caus":11,"thisexcept":1,"retriev":1,"method":3,"throwabl":2},"maxFreq":11,"totalTerms":48},"loc":5}